{"time": "2017-04-01 10:36:40,246", "message": "Exception on /api/monitor/KodiMon [PATCH]", "level": "ERROR", "name": "__main__"},
Traceback (most recent call last):
  File "C:\Python27\lib\site-packages\flask\app.py", line 1982, in wsgi_app
    response = self.full_dispatch_request()
  File "C:\Python27\lib\site-packages\flask\app.py", line 1615, in full_dispatch_request
    return self.finalize_request(rv)
  File "C:\Python27\lib\site-packages\flask\app.py", line 1630, in finalize_request
    response = self.make_response(rv)
  File "C:\Python27\lib\site-packages\flask\app.py", line 1740, in make_response
    rv = self.response_class.force_type(rv, request.environ)
  File "C:\Python27\lib\site-packages\werkzeug\wrappers.py", line 885, in force_type
    response = BaseResponse(*_run_wsgi_app(response, environ))
  File "C:\Python27\lib\site-packages\werkzeug\wrappers.py", line 57, in _run_wsgi_app
    return _run_wsgi_app(*args)
  File "C:\Python27\lib\site-packages\werkzeug\test.py", line 884, in run_wsgi_app
    app_rv = app(environ, start_response)
TypeError: 'dict' object is not callable
